Workbook

Sheet Đầu ra - Phiếu thu
J1: Chi tiết hạch toán
A2: Ngày hạch toán (*) | B2: Ngày chứng từ (*) | C2: Số chứng từ (*) | D2: Mã đối tượng | E2: Tên đối tượng | F2: Nộp vào TK | G2: Mở tại ngân hàng | H2: Lý do thu | I2: Diễn giải lý do thu | J2: Diễn giải (hạch toán) | K2: TK Nợ (*) | L2: TK Có (*) | M2: Số tiền | N2: Mã đối tượng (hạch toán)
A3: 22/04/2026 5423 - 24359 | B3: 22/04/2026 5423 - 24359 | F3: 9325252888 | G3: Ngân hàng TMCP Ngoại thương Việt Nam | J3: 6112IBT1iJYJQUQX.VU KHANH HUYEN transfer.20260422.135853.92822226688.VU KHANH HUYEN.970432 | K3: 1121 | M3: 225199200
A4: 22/04/2026 5211 - 77306 | B4: 22/04/2026 5211 - 77306 | F4: 9325252888 | G4: Ngân hàng TMCP Ngoại thương Việt Nam | J4: Chuyen khoan#ACH#0200970407042216363320261001278694.2026-04-22.163633.10556868.CONG TY TNHH TRUYEN THONG ASB.VTCBVNVN | K4: 1121 | M4: 7135800
A5: 25/04/2026 9701 - 9325252888 | B5: 25/04/2026 9701 - 9325252888 | F5: 9325252888 | G5: Ngân hàng TMCP Ngoại thương Việt Nam | J5: INTEREST PAYMENT | K5: 1121 | M5: 21502
A6: 05/05/2026 5425 - 58214 | B6: 05/05/2026 5425 - 58214 | F6: 9325252888 | G6: Ngân hàng TMCP Ngoại thương Việt Nam | J6: 6125IBT1iJ5IR5HH.VU KHANH HUYEN transfer.20260505.145005.92822226688.VU KHANH HUYEN.970432 | K6: 1121 | M6: 136596420
A7: 05/05/2026 5423 - 99294 | B7: 05/05/2026 5423 - 99294 | F7: 9325252888 | G7: Ngân hàng TMCP Ngoại thương Việt Nam | J7: 6125IBT1kCW5VY7U.Nop tm FT26125360091642.20260505.150108.8992345678.VU KHANH HUYEN.970407 | K7: 1121 | M7: 12185000
A8: 06/05/2026 5389 - 50040 | B8: 06/05/2026 5389 - 50040 | F8: 9325252888 | G8: Ngân hàng TMCP Ngoại thương Việt Nam | J8: KIEU TRUC TUNG Chuyen tien#SP#0200970488050609300220268wrs229599.5389.50040.093003 | K8: 1121 | M8: 25000000

Sheet Đầu ra - Phiếu chi
A1: Phương thức thanh toán | B1: Ngày hạch toán (*) | C1: Ngày chứng từ (*) | D1: Số chứng từ (*) | E1: Lý do chi | F1: Nội dung thanh toán | G1: Số tài khoản chi | H1: Tên ngân hàng chi | I1: Mã đối tượng | J1: Tên đối tượng | K1: Diễn giải (hạch toán) | L1: TK Nợ (*) | M1: TK Có (*) | N1: Số tiền | O1: Mã khoản mục chi phí | P1: Mã thống kê | Q1: Mã đơn vị
B2: 22/04/2026 | C2: 22/04/2026 | F2: Các khoản chi ngày 22/04/2026 | G2: 9325252888 | H2: Ngân hàng TMCP Ngoại thương Việt Nam | K2: MBVCB.13898417669.124466.noma back shopee.CT tu 9325252888 VU KHANH HUYEN toi 1602953979 PHAN ANH THAI tai MB | M2: 1121.1 | N2: 173360 | P2: =IF(AND(L2<>"",O2<>""),IFERROR(VLOOKUP(L2&"|"&O2,_ma_thong_ke!$A:$D,4,FALSE),""),"") | Q2: CPC
B3: 22/04/2026 | C3: 22/04/2026 | F3: Các khoản chi ngày 22/04/2026 | G3: 9325252888 | H3: Ngân hàng TMCP Ngoại thương Việt Nam | K3: MBVCB.13900584812.6112BFTVG23JT65N.vu khanh huyen.CT tu 9325252888 VU KHANH HUYEN toi 282000666 VU KHANH HUYEN tai VIB | M3: 1121.1 | N3: 101334834 | P3: =IF(AND(L3<>"",O3<>""),IFERROR(VLOOKUP(L3&"|"&O3,_ma_thong_ke!$A:$D,4,FALSE),""),"") | Q3: CPC
B4: 23/04/2026 | C4: 23/04/2026 | F4: Các khoản chi ngày 23/04/2026 | G4: 9325252888 | H4: Ngân hàng TMCP Ngoại thương Việt Nam | K4: MBVCB.13912678129.6113BFTVG23ZDZUF.claude.CT tu 9325252888 VU KHANH HUYEN toi 618408888888 NGUYEN BICH NGOC tai TECHCOMBANK | M4: 1121.1 | N4: 2100000 | P4: =IF(AND(L4<>"",O4<>""),IFERROR(VLOOKUP(L4&"|"&O4,_ma_thong_ke!$A:$D,4,FALSE),""),"") | Q4: CPC
B5: 23/04/2026 | C5: 23/04/2026 | F5: Các khoản chi ngày 23/04/2026 | G5: 9325252888 | H5: Ngân hàng TMCP Ngoại thương Việt Nam | K5: MBVCB.13912749938.6113BFTVG23ZDV91.150 d1 pro.CT tu 9325252888 VU KHANH HUYEN toi 3978069696 TRINH HOANG ANH tai TECHCOMBANK | M5: 1121.1 | N5: 84153580 | P5: =IF(AND(L5<>"",O5<>""),IFERROR(VLOOKUP(L5&"|"&O5,_ma_thong_ke!$A:$D,4,FALSE),""),"") | Q5: CPC
B6: 23/04/2026 | C6: 23/04/2026 | F6: Các khoản chi ngày 23/04/2026 | G6: 9325252888 | H6: Ngân hàng TMCP Ngoại thương Việt Nam | K6: MBVCB.13913009742.592760.thanh toan hoa hong.CT tu 9325252888 VU KHANH HUYEN toi 103872701702 NGUYEN TRONG HUNG tai VIETINBANK | M6: 1121.1 | N6: 6815000 | P6: =IF(AND(L6<>"",O6<>""),IFERROR(VLOOKUP(L6&"|"&O6,_ma_thong_ke!$A:$D,4,FALSE),""),"") | Q6: CPC
B7: 23/04/2026 | C7: 23/04/2026 | F7: Các khoản chi ngày 23/04/2026 | G7: 9325252888 | H7: Ngân hàng TMCP Ngoại thương Việt Nam | K7: MBVCB.13913027229.602028.nang cap o cung cho Van.CT tu 9325252888 VU KHANH HUYEN toi 0000013011997 NGUYEN THI THUY LINH tai MB | M7: 1121.1 | N7: 2194920 | P7: =IF(AND(L7<>"",O7<>""),IFERROR(VLOOKUP(L7&"|"&O7,_ma_thong_ke!$A:$D,4,FALSE),""),"") | Q7: CPC
B8: 23/04/2026 | C8: 23/04/2026 | F8: Các khoản chi ngày 23/04/2026 | G8: 9325252888 | H8: Ngân hàng TMCP Ngoại thương Việt Nam | K8: MBVCB.13913044239.6113BFTVG23ZN7WZ.vu khanh huyen.CT tu 9325252888 VU KHANH HUYEN toi 19037302881016 BUI QUANG PHUONG tai TECHCOMBANK | M8: 1121.1 | N8: 24194800 | P8: =IF(AND(L8<>"",O8<>""),IFERROR(VLOOKUP(L8&"|"&O8,_ma_thong_ke!$A:$D,4,FALSE),""),"") | Q8: CPC
B9: 27/04/2026 | C9: 27/04/2026 | F9: Các khoản chi ngày 27/04/2026 | G9: 9325252888 | H9: Ngân hàng TMCP Ngoại thương Việt Nam | K9: MBVCB.13966689799.QR Pay.Thanh toan cho 414541637 2764536 tu tai khoan 9325252888.Thanh toan QRCode | M9: 1121.1 | N9: 44999999 | P9: =IF(AND(L9<>"",O9<>""),IFERROR(VLOOKUP(L9&"|"&O9,_ma_thong_ke!$A:$D,4,FALSE),""),"") | Q9: CPC
B10: 27/04/2026 | C10: 27/04/2026 | F10: Các khoản chi ngày 27/04/2026 | G10: 9325252888 | H10: Ngân hàng TMCP Ngoại thương Việt Nam | K10: MBVCB.13969898880.6117BFTVG23HG7UD. doscom back tiktok.CT tu 9325252888 VU KHANH HUYEN toi 26296666679 KIEU TRUC TUNG tai VPBANK | M10: 1121.1 | N10: 2500000 | P10: =IF(AND(L10<>"",O10<>""),IFERROR(VLOOKUP(L10&"|"&O10,_ma_thong_ke!$A:$D,4,FALSE),""),"") | Q10: CPC
B11: 27/04/2026 | C11: 27/04/2026 | F11: Các khoản chi ngày 27/04/2026 | G11: 9325252888 | H11: Ngân hàng TMCP Ngoại thương Việt Nam | K11: MBVCB.13969935232.831674.claude.CT tu 9325252888 VU KHANH HUYEN toi 1000120021998 AN BAO LONG tai MB | M11: 1121.1 | N11: 3900000 | P11: =IF(AND(L11<>"",O11<>""),IFERROR(VLOOKUP(L11&"|"&O11,_ma_thong_ke!$A:$D,4,FALSE),""),"") | Q11: CPC
B12: 27/04/2026 | C12: 27/04/2026 | F12: Các khoản chi ngày 27/04/2026 | G12: 9325252888 | H12: Ngân hàng TMCP Ngoại thương Việt Nam | K12: MBVCB.13970389367.6117BFTVG23H92H2.chi tieu .CT tu 9325252888 VU KHANH HUYEN toi 282000666 VU KHANH HUYEN tai VIB | M12: 1121.1 | N12: 10000000 | P12: =IF(AND(L12<>"",O12<>""),IFERROR(VLOOKUP(L12&"|"&O12,_ma_thong_ke!$A:$D,4,FALSE),""),"") | Q12: CPC
B13: 28/04/2026 | C13: 28/04/2026 | F13: Các khoản chi ngày 28/04/2026 | G13: 9325252888 | H13: Ngân hàng TMCP Ngoại thương Việt Nam | K13: MBVCB.13980180077.620712.noma hoan tiktok.CT tu 9325252888 VU KHANH HUYEN toi 0986128489 NGUYEN TRONG SU tai MB | M13: 1121.1 | N13: 179000 | P13: =IF(AND(L13<>"",O13<>""),IFERROR(VLOOKUP(L13&"|"&O13,_ma_thong_ke!$A:$D,4,FALSE),""),"") | Q13: CPC
... B43: 07/05/2026 | C43: 07/05/2026 | F43: Các khoản chi ngày 07/05/2026 | G43: 9325252888 | H43: Ngân hàng TMCP Ngoại thương Việt Nam | K43: MBVCB.14105351540.QR Pay.Thanh toan cho 419152332 2764536 tu tai khoan 9325252888.Thanh toan QRCode | M43: 1121.1 | N43: 39999300 | P43: =IF(AND(L43<>"",O43<>""),IFERROR(VLOOKUP(L43&"|"&O43,_ma_thong_ke!$A:$D,4,FALSE),""),"") | Q43: CPC

Sheet LOG
A1: Thời gian | B1: Dòng đầu vào | C1: Sheet xử lý | D1: Loại cảnh báo | E1: Nội dung chi tiết

Sheet _ma_thong_ke
A1: Key | B1: TK Nợ | C1: Mã KMCP | D1: Mã thống kê
A2: 6411|D01 | B2: 6411 | C2: D01 | D2: TTPB01
A3: 6411|D02 | B3: 6411 | C3: D02 | D3: TTPB01
A4: 6411|D03 | B4: 6411 | C4: D03 | D4: TTPB01
A5: 6411|D04 | B5: 6411 | C5: D04 | D5: TTPB01
A6: 6411|D05 | B6: 6411 | C6: D05 | D6: TTPB06
A7: 6411|D06 | B7: 6411 | C7: D06 | D7: TTPB06
A8: 6411|D07 | B8: 6411 | C8: D07 | D8: TTPB06
A9: 6411|D08 | B9: 6411 | C9: D08 | D9: TTPB01
A10: 6411|D09 | B10: 6411 | C10: D09 | D10: TTPB01
A11: 6411|D10 | B11: 6411 | C11: D10 | D11: TTPB06
A12: 6411|D11 | B12: 6411 | C12: D11 | D12: TTPB01
... A26: 6415|D25 | B26: 6415 | C26: D25 | D26: TTPB06
A27: 6416|D26 | B27: 6416 | C27: D26
A28: 6416|D27 | B28: 6416 | C28: D27
A29: 6416|D28 | B29: 6416 | C29: D28
A30: 6412|D29 | B30: 6412 | C30: D29 | D30: TTPB01
A31: 6412|D30 | B31: 6412 | C31: D30 | D31: TTPB01
A32: 6419|D31 | B32: 6419 | C32: D31
A33: 6419|D32 | B33: 6419 | C33: D32
A34: 6419|D33 | B34: 6419 | C34: D33 | D34: TTPB06
A35: 6419|D34 | B35: 6419 | C35: D34
A36: 641.12|D35 | B36: 641.12 | C36: D35 | D36: TTPB01
A37: 641.12|D36 | B37: 641.12 | C37: D36 | D37: TTPB01
A38: 641.1|D37 | B38: 641.1 | C38: D37 | D38: TTPB06
A39: 641.1|D38 | B39: 641.1 | C39: D38 | D39: TTPB06
A40: 641.1|D39 | B40: 641.1 | C40: D39 | D40: TTPB06
A41: 641.1|D40 | B41: 641.1 | C41: D40 | D41: TTPB06
A42: 641.1|D41 | B42: 641.1 | C42: D41 | D42: TTPB06
A43: 6414|D42 | B43: 6414 | C43: D42 | D43: TTPB01
A44: 6413|D43 | B44: 6413 | C44: D43 | D44: TTPB01
A45: 6413|D44 | B45: 6413 | C45: D44 | D45: TTPB01
A46: 641.11|D45 | B46: 641.11 | C46: D45
A47: 641.11|D46 | B47: 641.11 | C47: D46 | D47: TTPB01
A48: 641.11|D47 | B48: 641.11 | C48: D47 | D48: TTPB01
A49: 6418|D48 | B49: 6418 | C49: D48 | D49: TTPB01
A50: 6418|D49 | B50: 6418 | C50: D49 | D50: TTPB01
A51: 6418|D50 | B51: 6418 | C51: D50 | D51: TTPB01
A52: 6418|D51 | B52: 6418 | C52: D51 | D52: TTPB01
A53: 6418|D52 | B53: 6418 | C53: D52 | D53: TTPB01
...
